Workbook

Sheet Stations
A1: Station | B1: Type | C1: Massif | D1: Département | E1: Code postal | F1: Commune | G1: Code INSEE | H1: Statut d'activité | I1: Latitude | J1: Longitude | K1: Altitude village (m) | L1: Domaine skiable | M1: Bas des pistes (m) | N1: Haut des pistes (m) | O1: Dénivelé skiable (m) | P1: Altitude médiane des pistes (m) | Q1: Pistes ≥ 2 000 m (% des km) | R1: Pistes du domaine (km) | S1: Nombre de pistes | T1: Remontées mécaniques | U1: Pistes vertes | V1: Pistes bleues | W1: Pistes rouges | X1: Pistes noires | Y1: Non classées / freeride | Z1: Distance station-pistes (km) | AA1: Réservation officielle (URL) | AB1: Moteur de réservation | AC1: Plan des pistes (PDF) | AD1: ID domaine OpenSkiMap | AE1: Fiche France Montagnes
A2: Abondance | B2: Station (France Montagnes) | C2: Alpes du Nord | D2: Haute-Savoie | E2: 74360 | F2: Abondance | G2: 74001 | H2: En activité | I2: 46.267387 | J2: 6.73173 | K2: 1050 | L2: Portes du Soleil (versant français) | M2: 920 | N2: 2230 | O2: =IF(OR(M2="",N2=""),"",N2-M2) -> 1310 | P2: 1565 | Q2: 0.047 | R2: 493.7 | S2: 762 | T2: 195 | U2: 120 | V2: 357 | W2: 210 | X2: 32 | Y2: 43 | Z2: 1.21 | AD2: d2b0e7c59ecf744d36ed6af54c15743910092fe2 | AE2: https://www.france-montagnes.com/sit/abondance-29204/
A3: Aillons-Margeriaz | B3: Station (France Montagnes) | C3: Alpes du Nord | D3: Savoie | E3: 73340 | F3: Aillon-le-Jeune | G3: 73004 | H3: En activité | I3: 45.642911 | J3: 6.062014 | K3: 1387 | L3: Aillon-Margériaz | M3: 1385 | N3: 1835 | O3: =IF(OR(M3="",N3=""),"",N3-M3) -> 450 | P3: 1581 | Q3: 0 | R3: 21.7 | S3: 43 | T3: 10 | U3: 8 | V3: 26 | W3: 3 | X3: 3 | Y3: 3 | Z3: 0.07 | AD3: df9a26b589d512af30d78fa6ad55e745a3a677e3 | AE3: https://www.france-montagnes.com/sit/aillons-margeriaz-28418/
A4: Aime 2000 | B4: Station (France Montagnes) | C4: Alpes du Nord | D4: Savoie | E4: 73210 | F4: Aime-la-Plagne | G4: 73006 | H4: En activité | I4: 45.51042 | J4: 6.66592 | K4: 2101 | L4: Paradiski (Les Arcs – La Plagne) | M4: 1199 | N4: 3216 | O4: =IF(OR(M4="",N4=""),"",N4-M4) -> 2017 | P4: 2076 | Q4: 0.598 | R4: 487.8 | S4: 680 | T4: 87 | U4: 47 | V4: 395 | W4: 150 | X4: 60 | Y4: 28 | Z4: 0.05 | AA4: https://www.laplagneresort.com/ | AB4: Ceto / Orchestra | AD4: dec537b602584db89d89ab114a619f1ae356398e
A5: Albiez Montrond | B5: Station (France Montagnes) | C5: Alpes du Nord | D5: Savoie | E5: 73300 | F5: Albiez-Montrond | G5: 73013 | H5: En activité | I5: 45.193509 | J5: 6.3441466 | K5: 1690 | L5: Albiez-Montrond | M5: 1490 | N5: 2012 | O5: =IF(OR(M5="",N5=""),"",N5-M5) -> 522 | P5: 1697 | Q5: 0.005 | R5: 17.2 | S5: 21 | T5: 7 | U5: 1 | V5: 8 | W5: 7 | X5: 2 | Y5: 3 | Z5: 1.36 | AA5: https://www.montagnicimes.com/albiez/ | AC5: https://anmsm.media.tourinsoft.eu/upload/Plan-pistes---Albiez-hiver-2023-2024.pdf | AD5: 78779b860e6b70a1d8e64ddb7cb458cedd26d005 | AE5: https://www.france-montagnes.com/sit/albiez-montrond-statanmsm2v500ql1/
A6: Alpe D'Huez | B6: Station (France Montagnes) | C6: Alpes du Nord | D6: Isère | E6: 38750 | F6: Huez | G6: 38191 | H6: En activité | I6: 45.0904 | J6: 6.0696 | K6: 1807 | L6: Alpe d'Huez Grand Domaine | M6: 1124 | N6: 3314 | O6: =IF(OR(M6="",N6=""),"",N6-M6) -> 2190 | P6: 1975 | Q6: 0.45 | R6: 190.2 | S6: 350 | T6: 82 | U6: 131 | V6: 89 | W6: 75 | X6: 33 | Y6: 22 | Z6: 0.22 | AA6: https://reservation.alpedhuez.com/?user-facet=winter | AB6: Ublo (ex-Valraiso/MSEM) | AC6: https://anmsm.media.tourinsoft.eu/upload/Alpe-d-huez-Alpin-2026.pdf | AD6: 721dd142d0af653027c7569e1bd0799586bdefa1 | AE6: https://www.france-montagnes.com/sit/alpe-dhuez-statanmsm01380001/
A7: Alpe Du Grand-Serre | B7: Station (France Montagnes) | C7: Alpes du Nord | D7: Isère | E7: 38350 | F7: La Morte | G7: 38264 | H7: En activité, avenir fragile | I7: 45.024468 | J7: 5.8612704 | K7: 1372 | L7: L'Alpe du Grand Serre | M7: 1363 | N7: 2166 | O7: =IF(OR(M7="",N7=""),"",N7-M7) -> 803 | P7: 1792 | Q7: 0.082 | R7: 36.7 | S7: 52 | T7: 14 | U7: 6 | V7: 28 | W7: 16 | X7: 2 | Z7: 0.12 | AA7: https://www.matheysine-tourisme.com/fr/alpedugrandserre/ | AB7: Open System | AC7: https://anmsm.media.tourinsoft.eu/upload/380002-09.jpg | AD7: c0e65ff5494198c3e504ff30257b990d92b29cfc | AE7: https://www.france-montagnes.com/sit/alpe-du-grand-serre-statanmsm01380002/
A8: Arc 1600 | B8: Station (France Montagnes) | C8: Alpes du Nord | D8: Savoie | E8: 73700 | F8: Bourg-Saint-Maurice | G8: 73054 | H8: En activité | I8: 45.59382 | J8: 6.7948 | K8: 1671 | L8: Paradiski (Les Arcs – La Plagne) | M8: 1199 | N8: 3216 | O8: =IF(OR(M8="",N8=""),"",N8-M8) -> 2017 | P8: 2076 | Q8: 0.598 | R8: 487.8 | S8: 680 | T8: 87 | U8: 47 | V8: 395 | W8: 150 | X8: 60 | Y8: 28 | Z8: 0.06 | AA8: https://www.lesarcs.com/ | AD8: dec537b602584db89d89ab114a619f1ae356398e
A9: Arc 1800 | B9: Station (France Montagnes) | C9: Alpes du Nord | D9: Savoie | E9: 73700 | F9: Bourg-Saint-Maurice | G9: 73054 | H9: En activité | I9: 45.57326 | J9: 6.78043 | K9: 1727 | L9: Paradiski (Les Arcs – La Plagne) | M9: 1199 | N9: 3216 | O9: =IF(OR(M9="",N9=""),"",N9-M9) -> 2017 | P9: 2076 | Q9: 0.598 | R9: 487.8 | S9: 680 | T9: 87 | U9: 47 | V9: 395 | W9: 150 | X9: 60 | Y9: 28 | Z9: 0.01 | AA9: https://www.lesarcs.com/ | AD9: dec537b602584db89d89ab114a619f1ae356398e
A10: Arc 1950 | B10: Station (France Montagnes) | C10: Alpes du Nord | D10: Savoie | E10: 73700 | F10: Bourg-Saint-Maurice | G10: 73054 | H10: En activité | I10: 45.57276 | J10: 6.8266 | K10: 2040 | L10: Paradiski (Les Arcs – La Plagne) | M10: 1199 | N10: 3216 | O10: =IF(OR(M10="",N10=""),"",N10-M10) -> 2017 | P10: 2076 | Q10: 0.598 | R10: 487.8 | S10: 680 | T10: 87 | U10: 47 | V10: 395 | W10: 150 | X10: 60 | Y10: 28 | Z10: 0.01 | AA10: https://www.lesarcs.com/ | AD10: dec537b602584db89d89ab114a619f1ae356398e
A11: Arc 2000 | B11: Station (France Montagnes) | C11: Alpes du Nord | D11: Savoie | E11: 73700 | F11: Bourg-Saint-Maurice | G11: 73054 | H11: En activité | I11: 45.57225 | J11: 6.83308 | K11: 2145 | L11: Paradiski (Les Arcs – La Plagne) | M11: 1199 | N11: 3216 | O11: =IF(OR(M11="",N11=""),"",N11-M11) -> 2017 | P11: 2076 | Q11: 0.598 | R11: 487.8 | S11: 680 | T11: 87 | U11: 47 | V11: 395 | W11: 150 | X11: 60 | Y11: 28 | Z11: 0.06 | AA11: https://www.lesarcs.com/ | AD11: dec537b602584db89d89ab114a619f1ae356398e
A12: Areches Beaufort | B12: Station (France Montagnes) | C12: Alpes du Nord | D12: Savoie | E12: 73270 | F12: Beaufort | G12: 73034 | H12: En activité | I12: 45.6864 | J12: 6.5707 | K12: 1065 | L12: Arêches Beaufort | M12: 1018 | N12: 2319 | O12: =IF(OR(M12="",N12=""),"",N12-M12) -> 1301 | P12: 1765 | Q12: 0.215 | R12: 36.1 | S12: 63 | T12: 15 | U12: 3 | V12: 37 | W12: 19 | X12: 3 | Y12: 1 | Z12: 0.4 | AA12: https://reservation.areches-beaufort.com/ | AB12: Ingénie / Genius | AC12: https://anmsm.media.tourinsoft.eu/upload/Plan-des-pistes-23-24-BD.pdf | AD12: 57b39abafcecc675add3a21c7b78bcda579aee64 | AE12: https://www.france-montagnes.com/sit/areches-beaufort-statanmsm01730002/
A13: Argentière | B13: Station (France Montagnes) | C13: Alpes du Nord | D13: Haute-Savoie | E13: 74400 | F13: Chamonix-Mont-Blanc | G13: 74056 | H13: En activité | I13: 45.984375 | J13: 6.929418 | K13: 1259 | L13: Les Grands Montets | M13: 1232 | N13: 3232 | O13: =IF(OR(M13="",N13=""),"",N13-M13) -> 2000 | P13: 2084 | Q13: 0.624 | R13: 39.9 | S13: 46 | T13: 9 | U13: 2 | V13: 15 | W13: 16 | X13: 12 | Y13: 1 | Z13: 0.63 | AD13: 77817eafde1b8d56ca0716d7a207b6c92d01743c | AE13: https://www.france-montagnes.com/sit/argentiere-570552/
A14: Auris en Oisans | B14: Station (France Montagnes) | C14: Alpes du Nord | D14: Isère | E14: 38142 | F14: Le Freney-d'Oisans | G14: 38173 | H14: En activité | I14: 45.047222 | J14: 6.125314 | K14: 945 | L14: Les Deux Alpes | M14: 1284 | N14: 3511 | O14: =IF(OR(M14="",N14=""),"",N14-M14) -> 2227 | P14: 2500 | Q14: 0.785 | R14: 144.5 | S14: 250 | T14: 46 | U14: 62 | V14: 137 | W14: 33 | X14: 17 | Y14: 1 | Z14: 1.56 | AD14: 5bd589496339e89cf9be3d93c86e7e6c41f72208 | AE14: https://www.france-montagnes.com/sit/auris-en-oisans-28430/
A15: Aussois | B15: Station (France Montagnes) | C15: Alpes du Nord | D15: Savoie | E15: 73500 | F15: Aussois | G15: 73023 | H15: En activité | I15: 45.2295 | J15: 6.7392 | K15: 1501 | L15: Espace Haute Maurienne Vanoise | M15: 1306 | N15: 2952 | O15: =IF(OR(M15="",N15=""),"",N15-M15) -> 1646 | P15: 2087 | Q15: 0.557 | R15: 255.4 | S15: 402 | T15: 79 | U15: 108 | V15: 136 | W15: 112 | X15: 20 | Y15: 26 | Z15: 0.22 | AA15: https://reservation.haute-maurienne-vanoise.com/ac62-aussois.htm | AB15: Open System | AC15: https://anmsm.media.tourinsoft.eu/upload/aussois-ge-une-ural-2016e.pdf | AD15: 44ee1a2c1392b07916bca601bb15230dca87e420 | AE15: https://www.france-montagnes.com/sit/aussois-statanmsm01730003/
A16: Autrans Méaudres en Vercors | B16: Station (France Montagnes) | C16: Alpes du Nord | D16: Isère | E16: 38880 | F16: Autrans-Méaudre en Vercors | G16: 38225 | H16: En activité | I16: 45.155316 | J16: 5.552751 | K16: 1040 | L16: Domaine Autrans - Méaudre | M16: 1003 | N16: 1607 | O16: =IF(OR(M16="",N16=""),"",N16-M16) -> 604 | P16: 1385 | Q16: 0 | R16: 19.6 | S16: 41 | T16: 13 | U16: 10 | V16: 14 | W16: 14 | X16: 3 | Z16: 3.97 | AD16: c4fe645047e06c17f033f3092f88a83b9f7012e2 | AE16: https://www.france-montagnes.com/sit/autrans-meaudres-en-vercors-28439/
A17: Avoriaz 1800 | B17: Station (France Montagnes) | C17: Alpes du Nord | D17: Haute-Savoie | E17: 74110 | F17: Morzine | G17: 74191 | H17: En activité | I17: 46.186097 | J17: 6.719237 | K17: 1351 | L17: Portes du Soleil (versant français) | M17: 920 | N17: 2230 | O17: =IF(OR(M17="",N17=""),"",N17-M17) -> 1310 | P17: 1565 | Q17: 0.047 | R17: 493.7 | S17: 762 | T17: 195 | U17: 120 | V17: 357 | W17: 210 | X17: 32 | Y17: 43 | Z17: 0.47 | AA17: https://reservation.avoriaz.com/ | AB17: Ingénie / Genius | AD17: d2b0e7c59ecf744d36ed6af54c15743910092fe2 | AE17: https://www.france-montagnes.com/sit/avoriaz-1800-28442/
A18: Belle Plagne | B18: Station (France Montagnes) | C18: Alpes du Nord | D18: Savoie | E18: 73210 | F18: La Plagne Tarentaise | G18: 73150 | H18: En activité | I18: 45.5082 | J18: 6.70685 | K18: 2068 | L18: Paradiski (Les Arcs – La Plagne) | M18: 1199 | N18: 3216 | O18: =IF(OR(M18="",N18=""),"",N18-M18) -> 2017 | P18: 2076 | Q18: 0.598 | R18: 487.8 | S18: 680 | T18: 87 | U18: 47 | V18: 395 | W18: 150 | X18: 60 | Y18: 28 | Z18: 0.06 | AA18: https://www.laplagneresort.com/ | AB18: Ceto / Orchestra | AD18: dec537b602584db89d89ab114a619f1ae356398e
A19: Bernex | B19: Station (France Montagnes) | C19: Alpes du Nord | D19: Haute-Savoie | E19: 74500 | F19: Bernex | G19: 74033 | H19: En activité | I19: 46.355269 | J19: 6.6755715 | K19: 978 | L19: Bernex | M19: 995 | N19: 1871 | O19: =IF(OR(M19="",N19=""),"",N19-M19) -> 876 | P19: 1335 | Q19: 0 | R19: 15.4 | S19: 45 | T19: 10 | U19: 2 | V19: 23 | W19: 14 | X19: 4 | Y19: 2 | Z19: 1.04 | AA19: https://www.bernexstation.fr/fr/ | AB19: Eliberty | AC19: https://anmsm.media.tourinsoft.eu/upload/Plan-pistes-Bernex-H-19-20internet2.pdf | AD19: 19b6e308caa6766b21cb00e4fb40a82c4ee1f95b | AE19: https://www.france-montagnes.com/sit/bernex-statanmsm01740063/
A20: Bessans | B20: Station (France Montagnes) | C20: Alpes du Nord | D20: Savoie | E20: 73480 | F20: Bessans | G20: 73040 | H20: En activité | I20: 45.323084 | J20: 7.022331 | K20: 1764 | L20: Espace Haute Maurienne Vanoise | M20: 1306 | N20: 2952 | O20: =IF(OR(M20="",N20=""),"",N20-M20) -> 1646 | P20: 2087 | Q20: 0.557 | R20: 255.4 | S20: 402 | T20: 79 | U20: 108 | V20: 136 | W20: 112 | X20: 20 | Y20: 26 | Z20: 2.3 | AD20: 44ee1a2c1392b07916bca601bb15230dca87e420 | AE20: https://www.france-montagnes.com/sit/bessans-28448/
A21: Bisanne 1500 | B21: Village-station | C21: Alpes du Nord | D21: Savoie | E21: 73270 | F21: Villard-sur-Doron | G21: 73317 | H21: En activité | I21: 45.73807 | J21: 6.50584 | K21: 1506 | L21: Espace Diamant | M21: 949 | N21: 2054 | O21: =IF(OR(M21="",N21=""),"",N21-M21) -> 1105 | P21: 1660 | Q21: 0.014 | R21: 225.6 | S21: 333 | T21: 85 | U21: 68 | V21: 165 | W21: 74 | X21: 13 | Y21: 13 | Z21: 0.05 | AA21: https://reservation.lessaisies.com/ | AB21: Ingénie / Genius | AD21: 0345d73f7a4bf0f49815ccb16306a3ec6371544b
A22: Bonneval Sur Arc | B22: Station (France Montagnes) | C22: Alpes du Nord | D22: Savoie | E22: 73480 | F22: Bonneval-sur-Arc | G22: 73047 | H22: En activité | I22: 45.3693 | J22: 7.0501 | K22: 1930 | L22: Espace Haute Maurienne Vanoise | M22: 1306 | N22: 2952 | O22: =IF(OR(M22="",N22=""),"",N22-M22) -> 1646 | P22: 2087 | Q22: 0.557 | R22: 255.4 | S22: 402 | T22: 79 | U22: 108 | V22: 136 | W22: 112 | X22: 20 | Y22: 26 | Z22: 0.4 | AA22: https://reservation.haute-maurienne-vanoise.com/ac64-bonneval-sur-arc.htm | AB22: Open System | AC22: https://anmsm.media.tourinsoft.eu/upload/730005-09.jpg | AD22: 44ee1a2c1392b07916bca601bb15230dca87e420 | AE22: https://www.france-montagnes.com/sit/bonneval-sur-arc-statanmsm01730005/
A23: Brides Les Bains | B23: Station (France Montagnes) | C23: Alpes du Nord | D23: Savoie | E23: 73570 | F23: Brides-les-Bains | G23: 73057 | H23: En activité | I23: 45.4546 | J23: 6.5697 | K23: 662 | L23: Les Trois Vallées | M23: 1110 | N23: 3223 | O23: =IF(OR(M23="",N23=""),"",N23-M23) -> 2113 | P23: 2252 | Q23: 0.728 | R23: 771.4 | S23: 871 | T23: 142 | U23: 168 | V23: 422 | W23: 222 | X23: 55 | Y23: 4 | Z23: 3.11 | AA23: https://brides-les-bains.secureticket.fr/provider/choisirsingleprovider | AC23: https://anmsm.media.tourinsoft.eu/upload/730007-09.jpg | AD23: 68b126bc3175516c9263aed7635d14e37ff360dc | AE23: https://www.france-montagnes.com/sit/brides-les-bains-statanmsm01730007/
A24: Chamonix Mont-Blanc | B24: Station (France Montagnes) | C24: Alpes du Nord | D24: Haute-Savoie | E24: 74400 | F24: Chamonix-Mont-Blanc | G24: 74056 | H24: En activité | I24: 45.948385 | J24: 6.893163 | K24: 1075 | L24: Brévent/Flégère (Chamonix) | M24: 1046 | N24: 2505 | O24: =IF(OR(M24="",N24=""),"",N24-M24) -> 1459 | P24: 1967 | Q24: 0.451 | R24: 55.1 | S24: 72 | T24: 18 | U24: 17 | V24: 19 | W24: 23 | X24: 13 | Z24: 0.6 | AA24: https://booking.chamonix.com/fr/ | AB24: Ceto / Orchestra | AD24: 8432e3c536835ef8a690f63b62060a7993bfd964 | AE24: https://www.france-montagnes.com/sit/chamonix-mont-blanc-28466/
A25: Champagny En Vanoise | B25: Station (France Montagnes) | C25: Alpes du Nord | D25: Savoie | E25: 73350 | F25: Champagny-en-Vanoise | G25: 73071 | H25: En activité | I25: 45.455823 | J25: 6.6935927 | K25: 1217 | L25: Paradiski (Les Arcs – La Plagne) | M25: 1199 | N25: 3216 | O25: =IF(OR(M25="",N25=""),"",N25-M25) -> 2017 | P25: 2076 | Q25: 0.598 | R25: 487.8 | S25: 680 | T25: 87 | U25: 47 | V25: 395 | W25: 150 | X25: 60 | Y25: 28 | Z25: 0.1 | AA25: https://www.laplagneresort.com/ | AB25: Ceto / Orchestra | AC25: https://anmsm.media.tourinsoft.eu/upload/PlanPistesParadiski.pdf | AD25: dec537b602584db89d89ab114a619f1ae356398e | AE25: https://www.france-montagnes.com/sit/champagny-en-vanoise-statanmsm01730009/
A26: Chamrousse | B26: Station (France Montagnes) | C26: Alpes du Nord | D26: Isère | E26: 38410 | F26: Chamrousse | G26: 38567 | H26: En activité | I26: 45.1229 | J26: 5.881 | K26: 1768 | L26: Chamrousse | M26: 1410 | N26: 2246 | O26: =IF(OR(M26="",N26=""),"",N26-M26) -> 836 | P26: 1879 | Q26: 0.235 | R26: 49.4 | S26: 117 | T26: 19 | U26: 13 | V26: 56 | W26: 41 | X26: 7 | Z26: 0.01 | AA26: https://www.chamrousse.com/hiver | AB26: Ingénie / Genius | AC26: https://anmsm.media.tourinsoft.eu/upload/PLAN-PISTES-2024-25-web.pdf | AD26: cf35c277ce2147943aff2aaa620572cc647a2a1d | AE26: https://www.france-montagnes.com/sit/chamrousse-statanmsm01380005/
A27: Chamrousse 1650 | B27: Village-station | C27: Alpes du Nord | D27: Isère | E27: 38410 | F27: Chamrousse | G27: 38567 | H27: En activité | I27: 45.12621 | J27: 5.87697 | K27: 1667 | L27: Chamrousse | M27: 1410 | N27: 2246 | O27: =IF(OR(M27="",N27=""),"",N27-M27) -> 836 | P27: 1879 | Q27: 0.235 | R27: 49.4 | S27: 117 | T27: 19 | U27: 13 | V27: 56 | W27: 41 | X27: 7 | Z27: 0.21 | AA27: https://www.chamrousse.com/hiver | AB27: Ingénie / Genius | AD27: cf35c277ce2147943aff2aaa620572cc647a2a1d
A28: Chamrousse 1750 | B28: Village-station | C28: Alpes du Nord | D28: Isère | E28: 38410 | F28: Chamrousse | G28: 38567 | H28: En activité | I28: 45.11244 | J28: 5.87671 | K28: 1752 | L28: Chamrousse | M28: 1410 | N28: 2246 | O28: =IF(OR(M28="",N28=""),"",N28-M28) -> 836 | P28: 1879 | Q28: 0.235 | R28: 49.4 | S28: 117 | T28: 19 | U28: 13 | V28: 56 | W28: 41 | X28: 7 | Z28: 0.17 | AA28: https://www.chamrousse.com/hiver | AB28: Ingénie / Genius | AD28: cf35c277ce2147943aff2aaa620572cc647a2a1d
A29: Chapelle d'Abondance | B29: Station (France Montagnes) | C29: Alpes du Nord | D29: Haute-Savoie | E29: 74360 | F29: La Chapelle-d'Abondance | G29: 74058 | H29: En activité | I29: 46.291356 | J29: 6.801207 | K29: 1013 | L29: Portes du Soleil (versant français) | M29: 920 | N29: 2230 | O29: =IF(OR(M29="",N29=""),"",N29-M29) -> 1310 | P29: 1565 | Q29: 0.047 | R29: 493.7 | S29: 762 | T29: 195 | U29: 120 | V29: 357 | W29: 210 | X29: 32 | Y29: 43 | Z29: 1.21 | AD29: d2b0e7c59ecf744d36ed6af54c15743910092fe2 | AE29: https://www.france-montagnes.com/sit/chapelle-dabondance-29207/
A30: Châtel | B30: Station (France Montagnes) | C30: Alpes du Nord | D30: Haute-Savoie | E30: 74390 | F30: Châtel | G30: 74063 | H30: En activité | I30: 46.25614 | J30: 6.81908 | K30: 1157 | L30: Portes du Soleil (versant français) | M30: 920 | N30: 2230 | O30: =IF(OR(M30="",N30=""),"",N30-M30) -> 1310 | P30: 1565 | Q30: 0.047 | R30: 493.7 | S30: 762 | T30: 195 | U30: 120 | V30: 357 | W30: 210 | X30: 32 | Y30: 43 | Z30: 0.28 | AD30: d2b0e7c59ecf744d36ed6af54c15743910092fe2 | AE30: https://www.france-montagnes.com/sit/chatel-28475/
A31: Col d'Ornon | B31: Station (France Montagnes) | C31: Alpes du Nord | D31: Isère | E31: 38520 | F31: Ornon | G31: 38285 | H31: En activité | I31: 45.039411 | J31: 5.978173 | K31: 1039 | L31: Domaine Alpin du Col d'Ornon | M31: 1332 | N31: 1867 | O31: =IF(OR(M31="",N31=""),"",N31-M31) -> 535 | P31: 1491 | Q31: 0 | R31: 6.1 | S31: 20 | T31: 4 | U31: 5 | V31: 3 | W31: 8 | X31: 3 | Y31: 1 | Z31: 0.92 | AD31: cfbdf0c0870e8baf8c048438de3175df84e88082 | AE31: https://www.france-montagnes.com/sit/col-dornon-28976/
A32: Col de l'Arzelier | B32: Station (France Montagnes) | C32: Alpes du Nord | D32: Isère | E32: 38650 | F32: Château-Bernard | G32: 38090 | H32: En activité | I32: 44.990682 | J32: 5.594928 | K32: 1152 | L32: Col de l'Arzelier | M32: 1156 | N32: 1491 | O32: =IF(OR(M32="",N32=""),"",N32-M32) -> 335 | P32: 1340 | Q32: 0 | R32: 3.5 | S32: 6 | T32: 0 | U32: 2 | V32: 1 | W32: 3 | Z32: 0.02 | AD32: a6471e912c17be98423d028110f4aa1ac55c1091 | AE32: https://www.france-montagnes.com/sit/col-de-larzelier-28994/
A33: Col du Rousset | B33: Station (France Montagnes) | C33: Alpes du Nord | D33: Drôme | E33: 26420 | F33: Saint-Agnan-en-Vercors | G33: 26290 | H33: En activité | I33: 44.8335 | J33: 5.4055 | K33: 1374 | L33: Station du Col de Rousset | M33: 1255 | N33: 1692 | O33: =IF(OR(M33="",N33=""),"",N33-M33) -> 437 | P33: 1446 | Q33: 0 | R33: 18 | S33: 32 | T33: 9 | U33: 18 | V33: 7 | W33: 5 | X33: 2 | Z33: 0.03 | AD33: 02707553d2b91ea36905797a8d6d66489860161d | AE33: https://www.france-montagnes.com/sit/col-du-rousset-28982/
A34: Combloux | B34: Station (France Montagnes) | C34: Alpes du Nord | D34: Haute-Savoie | E34: 74920 | F34: Combloux | G34: 74083 | H34: En activité | I34: 45.894569 | J34: 6.6447033 | K34: 976 | L34: Les Portes du Mont-Blanc | M34: 1017 | N34: 1925 | O34: =IF(OR(M34="",N34=""),"",N34-M34) -> 908 | P34: 1499 | Q34: 0 | R34: 89.5 | S34: 181 | T34: 30 | U34: 21 | V34: 66 | W34: 66 | X34: 18 | Y34: 10 | Z34: 0.95 | AA34: https://reservation.combloux.com/?lang=fr_FR | AB34: Ceto / Orchestra | AC34: https://anmsm.media.tourinsoft.eu/upload/plan-piste-portes-mont-blanc-web.pdf | AD34: aa87548d9445d366123e7ef7aee40af9d4a78dff | AE34: https://www.france-montagnes.com/sit/combloux-statanmsm01740009/
A35: Cordon | B35: Station (France Montagnes) | C35: Alpes du Nord | D35: Haute-Savoie | E35: 74700 | F35: Cordon | G35: 74089 | H35: En activité | I35: 45.913348 | J35: 6.597228 | K35: 1129 | L35: Les Portes du Mont-Blanc | M35: 1017 | N35: 1925 | O35: =IF(OR(M35="",N35=""),"",N35-M35) -> 908 | P35: 1499 | Q35: 0 | R35: 89.5 | S35: 181 | T35: 30 | U35: 21 | V35: 66 | W35: 66 | X35: 18 | Y35: 10 | Z35: 0.12 | AD35: aa87548d9445d366123e7ef7aee40af9d4a78dff | AE35: https://www.france-montagnes.com/sit/cordon-29267/
A36: Courchevel | B36: Station (France Montagnes) | C36: Alpes du Nord | D36: Savoie | E36: 73120 | F36: Courchevel | G36: 73227 | H36: En activité | I36: 45.4122 | J36: 6.6372 | K36: 1779 | L36: Les Trois Vallées | M36: 1110 | N36: 3223 | O36: =IF(OR(M36="",N36=""),"",N36-M36) -> 2113 | P36: 2252 | Q36: 0.728 | R36: 771.4 | S36: 871 | T36: 142 | U36: 168 | V36: 422 | W36: 222 | X36: 55 | Y36: 4 | Z36: 0.09 | AA36: https://reservation.courchevel.com/?lang=fr_FR | AB36: Ingénie / Genius | AC36: https://anmsm.media.tourinsoft.eu/upload/Panorama-Courchevel-2015-2016-V8--BAT5-.pdf | AD36: 68b126bc3175516c9263aed7635d14e37ff360dc | AE36: https://www.france-montagnes.com/sit/courchevel-statanmsm01730010/
A37: Courchevel Le Praz | B37: Station (France Montagnes) | C37: Alpes du Nord | D37: Savoie | E37: 73120 | F37: Courchevel | G37: 73227 | H37: En activité | I37: 45.43202 | J37: 6.62165 | K37: 1256 | L37: Les Trois Vallées | M37: 1110 | N37: 3223 | O37: =IF(OR(M37="",N37=""),"",N37-M37) -> 2113 | P37: 2252 | Q37: 0.728 | R37: 771.4 | S37: 871 | T37: 142 | U37: 168 | V37: 422 | W37: 222 | X37: 55 | Y37: 4 | Z37: 0.13 | AA37: https://reservation.courchevel.com/?lang=fr_FR | AB37: Ingénie / Genius | AD37: 68b126bc3175516c9263aed7635d14e37ff360dc
A38: Courchevel Moriond 1650 | B38: Station (France Montagnes) | C38: Alpes du Nord | D38: Savoie | E38: 73120 | F38: Courchevel | G38: 73227 | H38: En activité | I38: 45.41445 | J38: 6.64871 | K38: 1568 | L38: Les Trois Vallées | M38: 1110 | N38: 3223 | O38: =IF(OR(M38="",N38=""),"",N38-M38) -> 2113 | P38: 2252 | Q38: 0.728 | R38: 771.4 | S38: 871 | T38: 142 | U38: 168 | V38: 422 | W38: 222 | X38: 55 | Y38: 4 | Z38: 0.1 | AA38: https://reservation.courchevel.com/?lang=fr_FR | AB38: Ingénie / Genius | AD38: 68b126bc3175516c9263aed7635d14e37ff360dc
A39: Courchevel Village 1550 | B39: Station (France Montagnes) | C39: Alpes du Nord | D39: Savoie | E39: 73120 | F39: Courchevel | G39: 73227 | H39: En activité | I39: 45.42221 | J39: 6.64143 | K39: 1489 | L39: Les Trois Vallées | M39: 1110 | N39: 3223 | O39: =IF(OR(M39="",N39=""),"",N39-M39) -> 2113 | P39: 2252 | Q39: 0.728 | R39: 771.4 | S39: 871 | T39: 142 | U39: 168 | V39: 422 | W39: 222 | X39: 55 | Y39: 4 | Z39: 0.03 | AA39: https://reservation.courchevel.com/?lang=fr_FR | AB39: Ingénie / Genius | AD39: 68b126bc3175516c9263aed7635d14e37ff360dc
A40: Crest-Voland Cohennoz | B40: Station (France Montagnes) | C40: Alpes du Nord | D40: Savoie | E40: 73590 | F40: Crest-Voland | G40: 73094 | H40: En activité | I40: 45.794975 | J40: 6.505591 | K40: 1226 | L40: Espace Diamant | M40: 949 | N40: 2054 | O40: =IF(OR(M40="",N40=""),"",N40-M40) -> 1105 | P40: 1660 | Q40: 0.014 | R40: 225.6 | S40: 333 | T40: 85 | U40: 68 | V40: 165 | W40: 74 | X40: 13 | Y40: 13 | Z40: 0.08 | AA40: https://www.valdarly-montblanc.com/villages-stations/crest-voland-cohennoz/ | AB40: Ingénie / Genius | AC40: https://anmsm.media.tourinsoft.eu/upload/PLAN-PISTES-ZONES-CVC---ED.pdf | AD40: 0345d73f7a4bf0f49815ccb16306a3ec6371544b | AE40: https://www.france-montagnes.com/sit/crest-voland-cohennoz-statanmsm01730070/
...

Sheet Synthèse
A1: Répartition des stations par massif
A3: Massif | B3: Lignes (stations + villages) | C3: Avec domaine skiable | D3: Distance Paris moyenne (km) | E3: Altitude village moyenne (m) | F3: Haut des pistes le plus élevé (m) | G3: Stations skiant au-dessus de 2 000 m
A4: Alpes du Nord | B4: =COUNTIF(Stations!$C$2:$C$286,$A4) -> 156 | C4: =COUNTIFS(Stations!$C$2:$C$286,$A4,Stations!$N$2:$N$286,">0") -> 156 | D4: =ROUND(SUMIF(Stations!$C$2:$C$286,$A4,Stations!#REF!)/$B4,0) -> #REF! | E4: =ROUND(SUMIF(Stations!$C$2:$C$286,$A4,Stations!$K$2:$K$286)/$B4,0) -> 1371 | F4: =IF($C4=0,"",SUMPRODUCT(MAX((Stations!$C$2:$C$286=$A4)*Stations!$N$2:$N$286))) -> 3511 | G4: =COUNTIFS(Stations!$C$2:$C$286,$A4,Stations!$N$2:$N$286,">=2000") -> 121
A5: Alpes du Sud | B5: =COUNTIF(Stations!$C$2:$C$286,$A5) -> 54 | C5: =COUNTIFS(Stations!$C$2:$C$286,$A5,Stations!$N$2:$N$286,">0") -> 54 | D5: =ROUND(SUMIF(Stations!$C$2:$C$286,$A5,Stations!#REF!)/$B5,0) -> #REF! | E5: =ROUND(SUMIF(Stations!$C$2:$C$286,$A5,Stations!$K$2:$K$286)/$B5,0) -> 1531 | F5: =IF($C5=0,"",SUMPRODUCT(MAX((Stations!$C$2:$C$286=$A5)*Stations!$N$2:$N$286))) -> 2805 | G5: =COUNTIFS(Stations!$C$2:$C$286,$A5,Stations!$N$2:$N$286,">=2000") -> 41
A6: Jura | B6: =COUNTIF(Stations!$C$2:$C$286,$A6) -> 11 | C6: =COUNTIFS(Stations!$C$2:$C$286,$A6,Stations!$N$2:$N$286,">0") -> 11 | D6: =ROUND(SUMIF(Stations!$C$2:$C$286,$A6,Stations!#REF!)/$B6,0) -> #REF! | E6: =ROUND(SUMIF(Stations!$C$2:$C$286,$A6,Stations!$K$2:$K$286)/$B6,0) -> 931 | F6: =IF($C6=0,"",SUMPRODUCT(MAX((Stations!$C$2:$C$286=$A6)*Stations!$N$2:$N$286))) -> 1659 | G6: =COUNTIFS(Stations!$C$2:$C$286,$A6,Stations!$N$2:$N$286,">=2000") -> 0
A7: Massif Central | B7: =COUNTIF(Stations!$C$2:$C$286,$A7) -> 14 | C7: =COUNTIFS(Stations!$C$2:$C$286,$A7,Stations!$N$2:$N$286,">0") -> 13 | D7: =ROUND(SUMIF(Stations!$C$2:$C$286,$A7,Stations!#REF!)/$B7,0) -> #REF! | E7: =ROUND(SUMIF(Stations!$C$2:$C$286,$A7,Stations!$K$2:$K$286)/$B7,0) -> 1075 | F7: =IF($C7=0,"",SUMPRODUCT(MAX((Stations!$C$2:$C$286=$A7)*Stations!$N$2:$N$286))) -> 1834 | G7: =COUNTIFS(Stations!$C$2:$C$286,$A7,Stations!$N$2:$N$286,">=2000") -> 0
A8: Pyrénées | B8: =COUNTIF(Stations!$C$2:$C$286,$A8) -> 34 | C8: =COUNTIFS(Stations!$C$2:$C$286,$A8,Stations!$N$2:$N$286,">0") -> 34 | D8: =ROUND(SUMIF(Stations!$C$2:$C$286,$A8,Stations!#REF!)/$B8,0) -> #REF! | E8: =ROUND(SUMIF(Stations!$C$2:$C$286,$A8,Stations!$K$2:$K$286)/$B8,0) -> 1386 | F8: =IF($C8=0,"",SUMPRODUCT(MAX((Stations!$C$2:$C$286=$A8)*Stations!$N$2:$N$286))) -> 2530 | G8: =COUNTIFS(Stations!$C$2:$C$286,$A8,Stations!$N$2:$N$286,">=2000") -> 27
A9: Vosges | B9: =COUNTIF(Stations!$C$2:$C$286,$A9) -> 16 | C9: =COUNTIFS(Stations!$C$2:$C$286,$A9,Stations!$N$2:$N$286,">0") -> 16 | D9: =ROUND(SUMIF(Stations!$C$2:$C$286,$A9,Stations!#REF!)/$B9,0) -> #REF! | E9: =ROUND(SUMIF(Stations!$C$2:$C$286,$A9,Stations!$K$2:$K$286)/$B9,0) -> 858 | F9: =IF($C9=0,"",SUMPRODUCT(MAX((Stations!$C$2:$C$286=$A9)*Stations!$N$2:$N$286))) -> 1346 | G9: =COUNTIFS(Stations!$C$2:$C$286,$A9,Stations!$N$2:$N$286,">=2000") -> 0
A10: TOTAL | B10: =SUM(B4:B9) -> 285 | C10: =SUM(C4:C9) -> 284 | D10: =ROUND(SUM(Stations!#REF!)/$B10,0) -> #REF! | E10: =ROUND(SUM(Stations!$K$2:$K$286)/$B10,0) -> 1343 | F10: =ROUND(MAX(Stations!$N$2:$N$286),0) -> 3511 | G10: =SUM(G4:G9) -> 189

Sheet Paramètres
A1: Paramètres, sources et limites du fichier
A3: Point de référence | B3: Paris (Notre-Dame)
A4: Latitude référence | B4: 48.8566
A5: Longitude référence | B5: 2.3522
A6: Rayon terrestre (km) | B6: 6371
A8: Sources | B8: Stations, contacts et liens de réservation : France Montagnes (https://www.france-montagnes.com/les-stations-de-ski/), relevé du 18/08/2026, 233 stations. — Altitudes, longueurs de pistes et remontées : OpenSkiMap (https://tiles.openskimap.org/geojson/, export du 17/08/2026), qui agrège OpenStreetMap. — Altitude du village : IGN, RGE ALTI via l'API altimétrie de la Géoplateforme.
A9: Distance Paris (km) | B9: Distance orthodromique (à vol d'oiseau) calculée par formule depuis B4/B5. Ce n'est PAS une distance routière : comptez environ 1,25 à 1,4 fois cette valeur par la route. Modifiez B4/B5 pour recalculer depuis un autre point de départ.
A10: Altitude village (m) | B10: Altitude du sol au point exact de la station (coordonnées des colonnes F/G), interrogée sur le modèle numérique de terrain RGE ALTI de l'IGN. C'est l'altitude du village ou du front de neige, pas celle du domaine.
A11: Bas / haut des pistes | B11: Altitudes minimale et maximale relevées sur les tracés de pistes alpines du domaine skiable rattaché, calculées sur les 14 616 pistes françaises en exploitation d'OpenSkiMap (9 915 km cumulés). Ce sont des altitudes de DOMAINE : deux stations d'un même domaine relié (Les 3 Vallées, Paradiski, Espace Diamant…) portent logiquement les mêmes valeurs. Le dénivelé est la différence des deux, calculée par formule.
A12: Rattachement au domaine | B12: Chaque station est rattachée au domaine skiable dont les pistes sont les plus proches de ses coordonnées, par vote pondéré par la distance — et non par ressemblance de noms, trop fragile. La colonne « Distance station-pistes » donne l'écart à la piste la plus proche et la colonne « Fiabilité » le qualifie. Au-delà de 5 km, vérifiez avant d'exploiter la ligne.
A13: Colonnes de comptage | B13: « Pistes du domaine (km) », « Nombre de pistes », « Vertes / bleues », « Rouges / noires » et « Remontées mécaniques » décrivent le domaine entier, pas le secteur propre à la station. Les kilomètres sont mesurés sur les tracés OpenStreetMap et diffèrent souvent des chiffres commerciaux affichés par les stations.
A14: Km de pistes (France Montagnes) | B14: Chiffre repris du texte de présentation de la station quand il y figure (46 stations sur 233). Conservé à part pour pouvoir le confronter au calcul OpenSkiMap ; une cellule vide signifie « non communiqué », pas « zéro ».
A15: Stations sans domaine | B15: 9 stations n'ont aucune piste alpine cartographiée à moins de 15 km : Saint-Colomban-des-Villards, Le Chioula, Val de Morteau, Audibergue, Valdrôme, Névache, Artouste, Les Monts du Pilat, Soleilhas-Vauplane. Certaines sont à dominante nordique, d'autres sont simplement absentes d'OpenStreetMap. Leurs colonnes d'altitude de domaine sont vides — c'est une lacune connue, pas un zéro.
A16: Coordonnées | B16: Reprises des fiches France Montagnes puis contrôlées une à une par géocodage inverse (la commune trouvée doit correspondre au département du code postal) et par cohérence avec le domaine skiable rattaché. 33 stations échouaient à ces contrôles — certaines étaient placées à plus de 500 km de leur massif — et ont été recalées sur le chef-lieu de leur commune (API Adresse, data.gouv.fr) ou sur le centre du domaine (OpenSkiMap). La colonne « Origine coordonnées » indique la provenance ligne par ligne.
A17: Nommage d'un domaine | B17: OpenSkiMap étiquette l'ensemble du versant français des Portes du Soleil (9 stations, 494 km, 195 remontées) sous le nom d'un de ses secteurs, « Roc d'Enfer (La Grande Terche) ». La colonne « Domaine skiable » affiche « Portes du Soleil (versant français) » ; l'identifiant OpenSkiMap de la colonne AE reste celui de la source.
A18: Réservation officielle | B18: Trois sources, dans cet ordre de priorité : la liste d'URL que vous avez fournie (45), la page « sites de réservation » de France Montagnes (91 entrées, relevé du 18/08/2026), puis le lien « Réserver en ligne » de la fiche station. À défaut, le site officiel de la station a été lu pour y repérer un lien de réservation ; ces détections ne sont retenues que si l'hôte est un sous-domaine dédié (reservation./resa./booking.), partage le domaine du site officiel, ou correspond à un moteur connu. 101 stations sur 233 ont un lien. La colonne « Source du lien » dit d'où vient chaque URL, et porte le motif quand aucun lien n'a été retenu.
A19: Moteur de réservation | B19: Plateforme détectée en lisant la page de réservation (empreintes dans le HTML et l'URL finale). Ingénie/Genius 35, Open System 15, Ceto/Orchestra 10, Eliberty 4, Ublo (ex-Valraiso/MSEM) 3, WooCommerce 3, Elloha 1, Yoplanning 1 ; 29 non identifiés, le plus souvent parce que le moteur est chargé après un clic ou dans une iframe. C'est une observation à une date donnée, pas un engagement du prestataire.
... A25: Anomalie source signalée | B25: Prat Peyrot / Mont Aigoual : la fiche France Montagnes donne une adresse à Saint-Urcize (15110, Cantal) alors que la station est au Mont Aigoual (Gard). Commune, code postal et coordonnées corrigés ; la mention figure dans la colonne « Présentation » de la ligne.
